Workbook

Sheet HuongDan
A1: FORM | B1: KSKDK_TTHC — Thông tin hành chính
A2: FormId | B2: 1000092
A3: Cách dùng | B3: 1) Điền dữ liệu vào sheet NhapLieu (mỗi dòng = 1 người)
B4: 2) Cột danh mục: gõ tên viết tắt hoặc chọn từ gợi ý (vd: Phú Định → Phường Phú Định)
B5: 3) Ngày tháng: dd/MM/yyyy (ví dụ 29/07/2026)
B6: 4) Giới tính: Nam hoặc Nữ
B7: 5) Chạy: python3 import_excel.py --excel KSKDK_TTHC_mau_nhap.xlsx --user ... --password ...
A8: Gợi ý nhập | B8: Gõ vài ký tự đầu (vd: Phú Định, Hồ Chí Minh) — Excel lọc danh sách gợi ý
A9: Tên chuẩn | B9: Cột _Chuan_* (ẩn) tự khớp tên đầy đủ khi nhập tên viết tắt
B10: Không commit mật khẩu vào git

Sheet NhapLieu
A1: NgayKham | B1: DoiTuong | C1: DiaDiemKham | D1: HinhThucChiTra | E1: HinhThucKham | F1: NguonKhac_GhiRo | G1: CCCD | H1: HoTen | I1: NgaySinh | J1: GioiTinh | K1: DanToc | L1: NhomMau | M1: YeuToNhomMau | N1: BHYT | O1: SDT | P1: NoiOHienTai | Q1: TinhThanh | R1: XaPhuong | S1: NgheNghiepId | T1: NgheNghiep | U1: NoiCongTac | V1: XaPhuongCongTac | W1: LyDoKham | X1: _Chuan_B | Y1: _Chuan_C | Z1: _Chuan_D | AA1: _Chuan_E | AB1: _Chuan_J | AC1: _Chuan_K | AD1: _Chuan_L | AE1: _Chuan_M | AF1: _Chuan_Q | AG1: _Chuan_R | AH1: _Chuan_U
A2: dd/MM/yyyy — Ngày khám | B2: Chọn từ sheet DM_DoiTuong (điền Name hoặc Id) | C2: Chọn từ DM_DiaDiemKham | D2: Chọn từ DM_HinhThucChiTra | E2: Chọn từ DM_HinhThucKham | F2: Nếu hình thức chi trả = nguồn khác | G2: Số CCCD / định danh / hộ chiếu | H2: Họ tên IN HOA | I2: dd/MM/yyyy | J2: Nam hoặc Nữ | K2: Chọn từ DM_DanToc (mặc định: Kinh) | L2: A/B/O/AB — để trống nếu không có | M2: Rh+ / Rh- | N2: Số thẻ BHYT | O2: Điện thoại | P2: Số nhà, đường... | Q2: Chọn từ DM_TinhThanh | R2: Chọn từ DM_XaPhuong (theo tỉnh) | S2: Id nghề nghiệp nếu biết | T2: Tên nghề nghiệp (text) | U2: Id hoặc Name từ DM_NoiCongTac | V2: Xã/phường nơi công tác | W2: Lý do khám sức khỏe | X2: Tên chuẩn (ẩn) — tra cứu từ DM_DoiTuong | Y2: Tên chuẩn (ẩn) — tra cứu từ DM_DiaDiemKham | Z2: Tên chuẩn (ẩn) — tra cứu từ DM_HinhThucChiTra | AA2: Tên chuẩn (ẩn) — tra cứu từ DM_HinhThucKham | AB2: Tên chuẩn (ẩn) — tra cứu từ DM_GioiTinh | AC2: Tên chuẩn (ẩn) — tra cứu từ DM_DanToc | AD2: Tên chuẩn (ẩn) — tra cứu từ DM_NhomMau | AE2: Tên chuẩn (ẩn) — tra cứu từ DM_YeuToNhomMau | AF2: Tên chuẩn (ẩn) — tra cứu từ DM_TinhThanh | AG2: Tên chuẩn (ẩn) — tra cứu từ DM_XaPhuong | AH2: Tên chuẩn (ẩn) — tra cứu từ DM_NoiCongTac
A3: 23/07/2026 | B3: Người lao động (theo pháp luật về an toàn, vệ sinh lao động) | C3: Khám Lưu Động | D3: Ngân sách thành phố hỗ trợ | E3: Khám Theo Hợp Đồng | G3: 082185000807 | H3: NGUYỄN THỊ MƯỚT | I3: 22/04/1985 | J3: Nữ | O3: 0937721349 | P3: 1560/25/1E2 TỈNH LỘ 10 | Q3: Thành Phố Hồ Chí Minh | R3: Phường Bình Tân | T3: GIÁO VIÊN MẦM NON | W3: Khám sức khỏe định kỳ | X3: =IF(B3="","",IF(COUNTIF(DM_DoiTuong!$B:$B,B3),B3,IFERROR(INDEX(DM_DoiTuong!$B:$B,MATCH(B3,DM_DoiTuong!$C:$C,0)),B3))) | Y3: =IF(C3="","",IF(COUNTIF(DM_DiaDiemKham!$B:$B,C3),C3,IFERROR(INDEX(DM_DiaDiemKham!$B:$B,MATCH(C3,DM_DiaDiemKham!$C:$C,0)),C3))) | Z3: =IF(D3="","",IF(COUNTIF(DM_HinhThucChiTra!$B:$B,D3),D3,IFERROR(INDEX(DM_HinhThucChiTra!$B:$B,MATCH(D3,DM_HinhThucChiTra!$C:$C,0)),D3))) | AA3: =IF(E3="","",IF(COUNTIF(DM_HinhThucKham!$B:$B,E3),E3,IFERROR(INDEX(DM_HinhThucKham!$B:$B,MATCH(E3,DM_HinhThucKham!$C:$C,0)),E3))) | AB3: =IF(J3="","",IF(COUNTIF(DM_GioiTinh!$B:$B,J3),J3,IFERROR(INDEX(DM_GioiTinh!$B:$B,MATCH(J3,DM_GioiTinh!$C:$C,0)),J3))) | AC3: =IF(K3="","",IF(COUNTIF(DM_DanToc!$B:$B,K3),K3,IFERROR(INDEX(DM_DanToc!$B:$B,MATCH(K3,DM_DanToc!$C:$C,0)),K3))) | AD3: =IF(L3="","",IF(COUNTIF(DM_NhomMau!$B:$B,L3),L3,IFERROR(INDEX(DM_NhomMau!$B:$B,MATCH(L3,DM_NhomMau!$C:$C,0)),L3))) | AE3: =IF(M3="","",IF(COUNTIF(DM_YeuToNhomMau!$B:$B,M3),M3,IFERROR(INDEX(DM_YeuToNhomMau!$B:$B,MATCH(M3,DM_YeuToNhomMau!$C:$C,0)),M3))) | AF3: =IF(Q3="","",IF(COUNTIF(DM_TinhThanh!$B:$B,Q3),Q3,IFERROR(INDEX(DM_TinhThanh!$B:$B,MATCH(Q3,DM_TinhThanh!$C:$C,0)),Q3))) | AG3: =IF(R3="","",IF(COUNTIF(DM_XaPhuong!$B:$B,R3),R3,IFERROR(INDEX(DM_XaPhuong!$B:$B,MATCH(R3,DM_XaPhuong!$C:$C,0)),R3))) | AH3: =IF(U3="","",IF(COUNTIF(DM_NoiCongTac!$B:$B,U3),U3,IFERROR(INDEX(DM_NoiCongTac!$B:$B,MATCH(U3,DM_NoiCongTac!$C:$C,0)),U3)))
A4: 23/07/2026 | B4: Người lao động (theo pháp luật về an toàn, vệ sinh lao động) | C4: Khám Lưu Động | D4: Ngân sách thành phố hỗ trợ | E4: Khám Theo Hợp Đồng | G4: 079300009617 | H4: LÝ DƯƠNG NGỌC NGA | I4: 05/07/2000 | J4: Nữ | O4: 0708731758 | P4: 297/48 HẬU GIANG | Q4: Thành Phố Hồ Chí Minh | R4: Phường Bình Tây | T4: GIÁO VIÊN MẦM NON | W4: Khám sức khỏe định kỳ | X4: =IF(B4="","",IF(COUNTIF(DM_DoiTuong!$B:$B,B4),B4,IFERROR(INDEX(DM_DoiTuong!$B:$B,MATCH(B4,DM_DoiTuong!$C:$C,0)),B4))) | Y4: =IF(C4="","",IF(COUNTIF(DM_DiaDiemKham!$B:$B,C4),C4,IFERROR(INDEX(DM_DiaDiemKham!$B:$B,MATCH(C4,DM_DiaDiemKham!$C:$C,0)),C4))) | Z4: =IF(D4="","",IF(COUNTIF(DM_HinhThucChiTra!$B:$B,D4),D4,IFERROR(INDEX(DM_HinhThucChiTra!$B:$B,MATCH(D4,DM_HinhThucChiTra!$C:$C,0)),D4))) | AA4: =IF(E4="","",IF(COUNTIF(DM_HinhThucKham!$B:$B,E4),E4,IFERROR(INDEX(DM_HinhThucKham!$B:$B,MATCH(E4,DM_HinhThucKham!$C:$C,0)),E4))) | AB4: =IF(J4="","",IF(COUNTIF(DM_GioiTinh!$B:$B,J4),J4,IFERROR(INDEX(DM_GioiTinh!$B:$B,MATCH(J4,DM_GioiTinh!$C:$C,0)),J4))) | AC4: =IF(K4="","",IF(COUNTIF(DM_DanToc!$B:$B,K4),K4,IFERROR(INDEX(DM_DanToc!$B:$B,MATCH(K4,DM_DanToc!$C:$C,0)),K4))) | AD4: =IF(L4="","",IF(COUNTIF(DM_NhomMau!$B:$B,L4),L4,IFERROR(INDEX(DM_NhomMau!$B:$B,MATCH(L4,DM_NhomMau!$C:$C,0)),L4))) | AE4: =IF(M4="","",IF(COUNTIF(DM_YeuToNhomMau!$B:$B,M4),M4,IFERROR(INDEX(DM_YeuToNhomMau!$B:$B,MATCH(M4,DM_YeuToNhomMau!$C:$C,0)),M4))) | AF4: =IF(Q4="","",IF(COUNTIF(DM_TinhThanh!$B:$B,Q4),Q4,IFERROR(INDEX(DM_TinhThanh!$B:$B,MATCH(Q4,DM_TinhThanh!$C:$C,0)),Q4))) | AG4: =IF(R4="","",IF(COUNTIF(DM_XaPhuong!$B:$B,R4),R4,IFERROR(INDEX(DM_XaPhuong!$B:$B,MATCH(R4,DM_XaPhuong!$C:$C,0)),R4))) | AH4: =IF(U4="","",IF(COUNTIF(DM_NoiCongTac!$B:$B,U4),U4,IFERROR(INDEX(DM_NoiCongTac!$B:$B,MATCH(U4,DM_NoiCongTac!$C:$C,0)),U4)))
X5: =IF(B5="","",IF(COUNTIF(DM_DoiTuong!$B:$B,B5),B5,IFERROR(INDEX(DM_DoiTuong!$B:$B,MATCH(B5,DM_DoiTuong!$C:$C,0)),B5))) | Y5: =IF(C5="","",IF(COUNTIF(DM_DiaDiemKham!$B:$B,C5),C5,IFERROR(INDEX(DM_DiaDiemKham!$B:$B,MATCH(C5,DM_DiaDiemKham!$C:$C,0)),C5))) | Z5: =IF(D5="","",IF(COUNTIF(DM_HinhThucChiTra!$B:$B,D5),D5,IFERROR(INDEX(DM_HinhThucChiTra!$B:$B,MATCH(D5,DM_HinhThucChiTra!$C:$C,0)),D5))) | AA5: =IF(E5="","",IF(COUNTIF(DM_HinhThucKham!$B:$B,E5),E5,IFERROR(INDEX(DM_HinhThucKham!$B:$B,MATCH(E5,DM_HinhThucKham!$C:$C,0)),E5))) | AB5: =IF(J5="","",IF(COUNTIF(DM_GioiTinh!$B:$B,J5),J5,IFERROR(INDEX(DM_GioiTinh!$B:$B,MATCH(J5,DM_GioiTinh!$C:$C,0)),J5))) | AC5: =IF(K5="","",IF(COUNTIF(DM_DanToc!$B:$B,K5),K5,IFERROR(INDEX(DM_DanToc!$B:$B,MATCH(K5,DM_DanToc!$C:$C,0)),K5))) | AD5: =IF(L5="","",IF(COUNTIF(DM_NhomMau!$B:$B,L5),L5,IFERROR(INDEX(DM_NhomMau!$B:$B,MATCH(L5,DM_NhomMau!$C:$C,0)),L5))) | AE5: =IF(M5="","",IF(COUNTIF(DM_YeuToNhomMau!$B:$B,M5),M5,IFERROR(INDEX(DM_YeuToNhomMau!$B:$B,MATCH(M5,DM_YeuToNhomMau!$C:$C,0)),M5))) | AF5: =IF(Q5="","",IF(COUNTIF(DM_TinhThanh!$B:$B,Q5),Q5,IFERROR(INDEX(DM_TinhThanh!$B:$B,MATCH(Q5,DM_TinhThanh!$C:$C,0)),Q5))) | AG5: =IF(R5="","",IF(COUNTIF(DM_XaPhuong!$B:$B,R5),R5,IFERROR(INDEX(DM_XaPhuong!$B:$B,MATCH(R5,DM_XaPhuong!$C:$C,0)),R5))) | AH5: =IF(U5="","",IF(COUNTIF(DM_NoiCongTac!$B:$B,U5),U5,IFERROR(INDEX(DM_NoiCongTac!$B:$B,MATCH(U5,DM_NoiCongTac!$C:$C,0)),U5)))
X6: =IF(B6="","",IF(COUNTIF(DM_DoiTuong!$B:$B,B6),B6,IFERROR(INDEX(DM_DoiTuong!$B:$B,MATCH(B6,DM_DoiTuong!$C:$C,0)),B6))) | Y6: =IF(C6="","",IF(COUNTIF(DM_DiaDiemKham!$B:$B,C6),C6,IFERROR(INDEX(DM_DiaDiemKham!$B:$B,MATCH(C6,DM_DiaDiemKham!$C:$C,0)),C6))) | Z6: =IF(D6="","",IF(COUNTIF(DM_HinhThucChiTra!$B:$B,D6),D6,IFERROR(INDEX(DM_HinhThucChiTra!$B:$B,MATCH(D6,DM_HinhThucChiTra!$C:$C,0)),D6))) | AA6: =IF(E6="","",IF(COUNTIF(DM_HinhThucKham!$B:$B,E6),E6,IFERROR(INDEX(DM_HinhThucKham!$B:$B,MATCH(E6,DM_HinhThucKham!$C:$C,0)),E6))) | AB6: =IF(J6="","",IF(COUNTIF(DM_GioiTinh!$B:$B,J6),J6,IFERROR(INDEX(DM_GioiTinh!$B:$B,MATCH(J6,DM_GioiTinh!$C:$C,0)),J6))) | AC6: =IF(K6="","",IF(COUNTIF(DM_DanToc!$B:$B,K6),K6,IFERROR(INDEX(DM_DanToc!$B:$B,MATCH(K6,DM_DanToc!$C:$C,0)),K6))) | AD6: =IF(L6="","",IF(COUNTIF(DM_NhomMau!$B:$B,L6),L6,IFERROR(INDEX(DM_NhomMau!$B:$B,MATCH(L6,DM_NhomMau!$C:$C,0)),L6))) | AE6: =IF(M6="","",IF(COUNTIF(DM_YeuToNhomMau!$B:$B,M6),M6,IFERROR(INDEX(DM_YeuToNhomMau!$B:$B,MATCH(M6,DM_YeuToNhomMau!$C:$C,0)),M6))) | AF6: =IF(Q6="","",IF(COUNTIF(DM_TinhThanh!$B:$B,Q6),Q6,IFERROR(INDEX(DM_TinhThanh!$B:$B,MATCH(Q6,DM_TinhThanh!$C:$C,0)),Q6))) | AG6: =IF(R6="","",IF(COUNTIF(DM_XaPhuong!$B:$B,R6),R6,IFERROR(INDEX(DM_XaPhuong!$B:$B,MATCH(R6,DM_XaPhuong!$C:$C,0)),R6))) | AH6: =IF(U6="","",IF(COUNTIF(DM_NoiCongTac!$B:$B,U6),U6,IFERROR(INDEX(DM_NoiCongTac!$B:$B,MATCH(U6,DM_NoiCongTac!$C:$C,0)),U6)))
X7: =IF(B7="","",IF(COUNTIF(DM_DoiTuong!$B:$B,B7),B7,IFERROR(INDEX(DM_DoiTuong!$B:$B,MATCH(B7,DM_DoiTuong!$C:$C,0)),B7))) | Y7: =IF(C7="","",IF(COUNTIF(DM_DiaDiemKham!$B:$B,C7),C7,IFERROR(INDEX(DM_DiaDiemKham!$B:$B,MATCH(C7,DM_DiaDiemKham!$C:$C,0)),C7))) | Z7: =IF(D7="","",IF(COUNTIF(DM_HinhThucChiTra!$B:$B,D7),D7,IFERROR(INDEX(DM_HinhThucChiTra!$B:$B,MATCH(D7,DM_HinhThucChiTra!$C:$C,0)),D7))) | AA7: =IF(E7="","",IF(COUNTIF(DM_HinhThucKham!$B:$B,E7),E7,IFERROR(INDEX(DM_HinhThucKham!$B:$B,MATCH(E7,DM_HinhThucKham!$C:$C,0)),E7))) | AB7: =IF(J7="","",IF(COUNTIF(DM_GioiTinh!$B:$B,J7),J7,IFERROR(INDEX(DM_GioiTinh!$B:$B,MATCH(J7,DM_GioiTinh!$C:$C,0)),J7))) | AC7: =IF(K7="","",IF(COUNTIF(DM_DanToc!$B:$B,K7),K7,IFERROR(INDEX(DM_DanToc!$B:$B,MATCH(K7,DM_DanToc!$C:$C,0)),K7))) | AD7: =IF(L7="","",IF(COUNTIF(DM_NhomMau!$B:$B,L7),L7,IFERROR(INDEX(DM_NhomMau!$B:$B,MATCH(L7,DM_NhomMau!$C:$C,0)),L7))) | AE7: =IF(M7="","",IF(COUNTIF(DM_YeuToNhomMau!$B:$B,M7),M7,IFERROR(INDEX(DM_YeuToNhomMau!$B:$B,MATCH(M7,DM_YeuToNhomMau!$C:$C,0)),M7))) | AF7: =IF(Q7="","",IF(COUNTIF(DM_TinhThanh!$B:$B,Q7),Q7,IFERROR(INDEX(DM_TinhThanh!$B:$B,MATCH(Q7,DM_TinhThanh!$C:$C,0)),Q7))) | AG7: =IF(R7="","",IF(COUNTIF(DM_XaPhuong!$B:$B,R7),R7,IFERROR(INDEX(DM_XaPhuong!$B:$B,MATCH(R7,DM_XaPhuong!$C:$C,0)),R7))) | AH7: =IF(U7="","",IF(COUNTIF(DM_NoiCongTac!$B:$B,U7),U7,IFERROR(INDEX(DM_NoiCongTac!$B:$B,MATCH(U7,DM_NoiCongTac!$C:$C,0)),U7)))
X8: =IF(B8="","",IF(COUNTIF(DM_DoiTuong!$B:$B,B8),B8,IFERROR(INDEX(DM_DoiTuong!$B:$B,MATCH(B8,DM_DoiTuong!$C:$C,0)),B8))) | Y8: =IF(C8="","",IF(COUNTIF(DM_DiaDiemKham!$B:$B,C8),C8,IFERROR(INDEX(DM_DiaDiemKham!$B:$B,MATCH(C8,DM_DiaDiemKham!$C:$C,0)),C8))) | Z8: =IF(D8="","",IF(COUNTIF(DM_HinhThucChiTra!$B:$B,D8),D8,IFERROR(INDEX(DM_HinhThucChiTra!$B:$B,MATCH(D8,DM_HinhThucChiTra!$C:$C,0)),D8))) | AA8: =IF(E8="","",IF(COUNTIF(DM_HinhThucKham!$B:$B,E8),E8,IFERROR(INDEX(DM_HinhThucKham!$B:$B,MATCH(E8,DM_HinhThucKham!$C:$C,0)),E8))) | AB8: =IF(J8="","",IF(COUNTIF(DM_GioiTinh!$B:$B,J8),J8,IFERROR(INDEX(DM_GioiTinh!$B:$B,MATCH(J8,DM_GioiTinh!$C:$C,0)),J8))) | AC8: =IF(K8="","",IF(COUNTIF(DM_DanToc!$B:$B,K8),K8,IFERROR(INDEX(DM_DanToc!$B:$B,MATCH(K8,DM_DanToc!$C:$C,0)),K8))) | AD8: =IF(L8="","",IF(COUNTIF(DM_NhomMau!$B:$B,L8),L8,IFERROR(INDEX(DM_NhomMau!$B:$B,MATCH(L8,DM_NhomMau!$C:$C,0)),L8))) | AE8: =IF(M8="","",IF(COUNTIF(DM_YeuToNhomMau!$B:$B,M8),M8,IFERROR(INDEX(DM_YeuToNhomMau!$B:$B,MATCH(M8,DM_YeuToNhomMau!$C:$C,0)),M8))) | AF8: =IF(Q8="","",IF(COUNTIF(DM_TinhThanh!$B:$B,Q8),Q8,IFERROR(INDEX(DM_TinhThanh!$B:$B,MATCH(Q8,DM_TinhThanh!$C:$C,0)),Q8))) | AG8: =IF(R8="","",IF(COUNTIF(DM_XaPhuong!$B:$B,R8),R8,IFERROR(INDEX(DM_XaPhuong!$B:$B,MATCH(R8,DM_XaPhuong!$C:$C,0)),R8))) | AH8: =IF(U8="","",IF(COUNTIF(DM_NoiCongTac!$B:$B,U8),U8,IFERROR(INDEX(DM_NoiCongTac!$B:$B,MATCH(U8,DM_NoiCongTac!$C:$C,0)),U8)))
X9: =IF(B9="","",IF(COUNTIF(DM_DoiTuong!$B:$B,B9),B9,IFERROR(INDEX(DM_DoiTuong!$B:$B,MATCH(B9,DM_DoiTuong!$C:$C,0)),B9))) | Y9: =IF(C9="","",IF(COUNTIF(DM_DiaDiemKham!$B:$B,C9),C9,IFERROR(INDEX(DM_DiaDiemKham!$B:$B,MATCH(C9,DM_DiaDiemKham!$C:$C,0)),C9))) | Z9: =IF(D9="","",IF(COUNTIF(DM_HinhThucChiTra!$B:$B,D9),D9,IFERROR(INDEX(DM_HinhThucChiTra!$B:$B,MATCH(D9,DM_HinhThucChiTra!$C:$C,0)),D9))) | AA9: =IF(E9="","",IF(COUNTIF(DM_HinhThucKham!$B:$B,E9),E9,IFERROR(INDEX(DM_HinhThucKham!$B:$B,MATCH(E9,DM_HinhThucKham!$C:$C,0)),E9))) | AB9: =IF(J9="","",IF(COUNTIF(DM_GioiTinh!$B:$B,J9),J9,IFERROR(INDEX(DM_GioiTinh!$B:$B,MATCH(J9,DM_GioiTinh!$C:$C,0)),J9))) | AC9: =IF(K9="","",IF(COUNTIF(DM_DanToc!$B:$B,K9),K9,IFERROR(INDEX(DM_DanToc!$B:$B,MATCH(K9,DM_DanToc!$C:$C,0)),K9))) | AD9: =IF(L9="","",IF(COUNTIF(DM_NhomMau!$B:$B,L9),L9,IFERROR(INDEX(DM_NhomMau!$B:$B,MATCH(L9,DM_NhomMau!$C:$C,0)),L9))) | AE9: =IF(M9="","",IF(COUNTIF(DM_YeuToNhomMau!$B:$B,M9),M9,IFERROR(INDEX(DM_YeuToNhomMau!$B:$B,MATCH(M9,DM_YeuToNhomMau!$C:$C,0)),M9))) | AF9: =IF(Q9="","",IF(COUNTIF(DM_TinhThanh!$B:$B,Q9),Q9,IFERROR(INDEX(DM_TinhThanh!$B:$B,MATCH(Q9,DM_TinhThanh!$C:$C,0)),Q9))) | AG9: =IF(R9="","",IF(COUNTIF(DM_XaPhuong!$B:$B,R9),R9,IFERROR(INDEX(DM_XaPhuong!$B:$B,MATCH(R9,DM_XaPhuong!$C:$C,0)),R9))) | AH9: =IF(U9="","",IF(COUNTIF(DM_NoiCongTac!$B:$B,U9),U9,IFERROR(INDEX(DM_NoiCongTac!$B:$B,MATCH(U9,DM_NoiCongTac!$C:$C,0)),U9)))
X10: =IF(B10="","",IF(COUNTIF(DM_DoiTuong!$B:$B,B10),B10,IFERROR(INDEX(DM_DoiTuong!$B:$B,MATCH(B10,DM_DoiTuong!$C:$C,0)),B10))) | Y10: =IF(C10="","",IF(COUNTIF(DM_DiaDiemKham!$B:$B,C10),C10,IFERROR(INDEX(DM_DiaDiemKham!$B:$B,MATCH(C10,DM_DiaDiemKham!$C:$C,0)),C10))) | Z10: =IF(D10="","",IF(COUNTIF(DM_HinhThucChiTra!$B:$B,D10),D10,IFERROR(INDEX(DM_HinhThucChiTra!$B:$B,MATCH(D10,DM_HinhThucChiTra!$C:$C,0)),D10))) | AA10: =IF(E10="","",IF(COUNTIF(DM_HinhThucKham!$B:$B,E10),E10,IFERROR(INDEX(DM_HinhThucKham!$B:$B,MATCH(E10,DM_HinhThucKham!$C:$C,0)),E10))) | AB10: =IF(J10="","",IF(COUNTIF(DM_GioiTinh!$B:$B,J10),J10,IFERROR(INDEX(DM_GioiTinh!$B:$B,MATCH(J10,DM_GioiTinh!$C:$C,0)),J10))) | AC10: =IF(K10="","",IF(COUNTIF(DM_DanToc!$B:$B,K10),K10,IFERROR(INDEX(DM_DanToc!$B:$B,MATCH(K10,DM_DanToc!$C:$C,0)),K10))) | AD10: =IF(L10="","",IF(COUNTIF(DM_NhomMau!$B:$B,L10),L10,IFERROR(INDEX(DM_NhomMau!$B:$B,MATCH(L10,DM_NhomMau!$C:$C,0)),L10))) | AE10: =IF(M10="","",IF(COUNTIF(DM_YeuToNhomMau!$B:$B,M10),M10,IFERROR(INDEX(DM_YeuToNhomMau!$B:$B,MATCH(M10,DM_YeuToNhomMau!$C:$C,0)),M10))) | AF10: =IF(Q10="","",IF(COUNTIF(DM_TinhThanh!$B:$B,Q10),Q10,IFERROR(INDEX(DM_TinhThanh!$B:$B,MATCH(Q10,DM_TinhThanh!$C:$C,0)),Q10))) | AG10: =IF(R10="","",IF(COUNTIF(DM_XaPhuong!$B:$B,R10),R10,IFERROR(INDEX(DM_XaPhuong!$B:$B,MATCH(R10,DM_XaPhuong!$C:$C,0)),R10))) | AH10: =IF(U10="","",IF(COUNTIF(DM_NoiCongTac!$B:$B,U10),U10,IFERROR(INDEX(DM_NoiCongTac!$B:$B,MATCH(U10,DM_NoiCongTac!$C:$C,0)),U10)))
X11: =IF(B11="","",IF(COUNTIF(DM_DoiTuong!$B:$B,B11),B11,IFERROR(INDEX(DM_DoiTuong!$B:$B,MATCH(B11,DM_DoiTuong!$C:$C,0)),B11))) | Y11: =IF(C11="","",IF(COUNTIF(DM_DiaDiemKham!$B:$B,C11),C11,IFERROR(INDEX(DM_DiaDiemKham!$B:$B,MATCH(C11,DM_DiaDiemKham!$C:$C,0)),C11))) | Z11: =IF(D11="","",IF(COUNTIF(DM_HinhThucChiTra!$B:$B,D11),D11,IFERROR(INDEX(DM_HinhThucChiTra!$B:$B,MATCH(D11,DM_HinhThucChiTra!$C:$C,0)),D11))) | AA11: =IF(E11="","",IF(COUNTIF(DM_HinhThucKham!$B:$B,E11),E11,IFERROR(INDEX(DM_HinhThucKham!$B:$B,MATCH(E11,DM_HinhThucKham!$C:$C,0)),E11))) | AB11: =IF(J11="","",IF(COUNTIF(DM_GioiTinh!$B:$B,J11),J11,IFERROR(INDEX(DM_GioiTinh!$B:$B,MATCH(J11,DM_GioiTinh!$C:$C,0)),J11))) | AC11: =IF(K11="","",IF(COUNTIF(DM_DanToc!$B:$B,K11),K11,IFERROR(INDEX(DM_DanToc!$B:$B,MATCH(K11,DM_DanToc!$C:$C,0)),K11))) | AD11: =IF(L11="","",IF(COUNTIF(DM_NhomMau!$B:$B,L11),L11,IFERROR(INDEX(DM_NhomMau!$B:$B,MATCH(L11,DM_NhomMau!$C:$C,0)),L11))) | AE11: =IF(M11="","",IF(COUNTIF(DM_YeuToNhomMau!$B:$B,M11),M11,IFERROR(INDEX(DM_YeuToNhomMau!$B:$B,MATCH(M11,DM_YeuToNhomMau!$C:$C,0)),M11))) | AF11: =IF(Q11="","",IF(COUNTIF(DM_TinhThanh!$B:$B,Q11),Q11,IFERROR(INDEX(DM_TinhThanh!$B:$B,MATCH(Q11,DM_TinhThanh!$C:$C,0)),Q11))) | AG11: =IF(R11="","",IF(COUNTIF(DM_XaPhuong!$B:$B,R11),R11,IFERROR(INDEX(DM_XaPhuong!$B:$B,MATCH(R11,DM_XaPhuong!$C:$C,0)),R11))) | AH11: =IF(U11="","",IF(COUNTIF(DM_NoiCongTac!$B:$B,U11),U11,IFERROR(INDEX(DM_NoiCongTac!$B:$B,MATCH(U11,DM_NoiCongTac!$C:$C,0)),U11)))
X12: =IF(B12="","",IF(COUNTIF(DM_DoiTuong!$B:$B,B12),B12,IFERROR(INDEX(DM_DoiTuong!$B:$B,MATCH(B12,DM_DoiTuong!$C:$C,0)),B12))) | Y12: =IF(C12="","",IF(COUNTIF(DM_DiaDiemKham!$B:$B,C12),C12,IFERROR(INDEX(DM_DiaDiemKham!$B:$B,MATCH(C12,DM_DiaDiemKham!$C:$C,0)),C12))) | Z12: =IF(D12="","",IF(COUNTIF(DM_HinhThucChiTra!$B:$B,D12),D12,IFERROR(INDEX(DM_HinhThucChiTra!$B:$B,MATCH(D12,DM_HinhThucChiTra!$C:$C,0)),D12))) | AA12: =IF(E12="","",IF(COUNTIF(DM_HinhThucKham!$B:$B,E12),E12,IFERROR(INDEX(DM_HinhThucKham!$B:$B,MATCH(E12,DM_HinhThucKham!$C:$C,0)),E12))) | AB12: =IF(J12="","",IF(COUNTIF(DM_GioiTinh!$B:$B,J12),J12,IFERROR(INDEX(DM_GioiTinh!$B:$B,MATCH(J12,DM_GioiTinh!$C:$C,0)),J12))) | AC12: =IF(K12="","",IF(COUNTIF(DM_DanToc!$B:$B,K12),K12,IFERROR(INDEX(DM_DanToc!$B:$B,MATCH(K12,DM_DanToc!$C:$C,0)),K12))) | AD12: =IF(L12="","",IF(COUNTIF(DM_NhomMau!$B:$B,L12),L12,IFERROR(INDEX(DM_NhomMau!$B:$B,MATCH(L12,DM_NhomMau!$C:$C,0)),L12))) | AE12: =IF(M12="","",IF(COUNTIF(DM_YeuToNhomMau!$B:$B,M12),M12,IFERROR(INDEX(DM_YeuToNhomMau!$B:$B,MATCH(M12,DM_YeuToNhomMau!$C:$C,0)),M12))) | AF12: =IF(Q12="","",IF(COUNTIF(DM_TinhThanh!$B:$B,Q12),Q12,IFERROR(INDEX(DM_TinhThanh!$B:$B,MATCH(Q12,DM_TinhThanh!$C:$C,0)),Q12))) | AG12: =IF(R12="","",IF(COUNTIF(DM_XaPhuong!$B:$B,R12),R12,IFERROR(INDEX(DM_XaPhuong!$B:$B,MATCH(R12,DM_XaPhuong!$C:$C,0)),R12))) | AH12: =IF(U12="","",IF(COUNTIF(DM_NoiCongTac!$B:$B,U12),U12,IFERROR(INDEX(DM_NoiCongTac!$B:$B,MATCH(U12,DM_NoiCongTac!$C:$C,0)),U12)))
X13: =IF(B13="","",IF(COUNTIF(DM_DoiTuong!$B:$B,B13),B13,IFERROR(INDEX(DM_DoiTuong!$B:$B,MATCH(B13,DM_DoiTuong!$C:$C,0)),B13))) | Y13: =IF(C13="","",IF(COUNTIF(DM_DiaDiemKham!$B:$B,C13),C13,IFERROR(INDEX(DM_DiaDiemKham!$B:$B,MATCH(C13,DM_DiaDiemKham!$C:$C,0)),C13))) | Z13: =IF(D13="","",IF(COUNTIF(DM_HinhThucChiTra!$B:$B,D13),D13,IFERROR(INDEX(DM_HinhThucChiTra!$B:$B,MATCH(D13,DM_HinhThucChiTra!$C:$C,0)),D13))) | AA13: =IF(E13="","",IF(COUNTIF(DM_HinhThucKham!$B:$B,E13),E13,IFERROR(INDEX(DM_HinhThucKham!$B:$B,MATCH(E13,DM_HinhThucKham!$C:$C,0)),E13))) | AB13: =IF(J13="","",IF(COUNTIF(DM_GioiTinh!$B:$B,J13),J13,IFERROR(INDEX(DM_GioiTinh!$B:$B,MATCH(J13,DM_GioiTinh!$C:$C,0)),J13))) | AC13: =IF(K13="","",IF(COUNTIF(DM_DanToc!$B:$B,K13),K13,IFERROR(INDEX(DM_DanToc!$B:$B,MATCH(K13,DM_DanToc!$C:$C,0)),K13))) | AD13: =IF(L13="","",IF(COUNTIF(DM_NhomMau!$B:$B,L13),L13,IFERROR(INDEX(DM_NhomMau!$B:$B,MATCH(L13,DM_NhomMau!$C:$C,0)),L13))) | AE13: =IF(M13="","",IF(COUNTIF(DM_YeuToNhomMau!$B:$B,M13),M13,IFERROR(INDEX(DM_YeuToNhomMau!$B:$B,MATCH(M13,DM_YeuToNhomMau!$C:$C,0)),M13))) | AF13: =IF(Q13="","",IF(COUNTIF(DM_TinhThanh!$B:$B,Q13),Q13,IFERROR(INDEX(DM_TinhThanh!$B:$B,MATCH(Q13,DM_TinhThanh!$C:$C,0)),Q13))) | AG13: =IF(R13="","",IF(COUNTIF(DM_XaPhuong!$B:$B,R13),R13,IFERROR(INDEX(DM_XaPhuong!$B:$B,MATCH(R13,DM_XaPhuong!$C:$C,0)),R13))) | AH13: =IF(U13="","",IF(COUNTIF(DM_NoiCongTac!$B:$B,U13),U13,IFERROR(INDEX(DM_NoiCongTac!$B:$B,MATCH(U13,DM_NoiCongTac!$C:$C,0)),U13)))
X14: =IF(B14="","",IF(COUNTIF(DM_DoiTuong!$B:$B,B14),B14,IFERROR(INDEX(DM_DoiTuong!$B:$B,MATCH(B14,DM_DoiTuong!$C:$C,0)),B14))) | Y14: =IF(C14="","",IF(COUNTIF(DM_DiaDiemKham!$B:$B,C14),C14,IFERROR(INDEX(DM_DiaDiemKham!$B:$B,MATCH(C14,DM_DiaDiemKham!$C:$C,0)),C14))) | Z14: =IF(D14="","",IF(COUNTIF(DM_HinhThucChiTra!$B:$B,D14),D14,IFERROR(INDEX(DM_HinhThucChiTra!$B:$B,MATCH(D14,DM_HinhThucChiTra!$C:$C,0)),D14))) | AA14: =IF(E14="","",IF(COUNTIF(DM_HinhThucKham!$B:$B,E14),E14,IFERROR(INDEX(DM_HinhThucKham!$B:$B,MATCH(E14,DM_HinhThucKham!$C:$C,0)),E14))) | AB14: =IF(J14="","",IF(COUNTIF(DM_GioiTinh!$B:$B,J14),J14,IFERROR(INDEX(DM_GioiTinh!$B:$B,MATCH(J14,DM_GioiTinh!$C:$C,0)),J14))) | AC14: =IF(K14="","",IF(COUNTIF(DM_DanToc!$B:$B,K14),K14,IFERROR(INDEX(DM_DanToc!$B:$B,MATCH(K14,DM_DanToc!$C:$C,0)),K14))) | AD14: =IF(L14="","",IF(COUNTIF(DM_NhomMau!$B:$B,L14),L14,IFERROR(INDEX(DM_NhomMau!$B:$B,MATCH(L14,DM_NhomMau!$C:$C,0)),L14))) | AE14: =IF(M14="","",IF(COUNTIF(DM_YeuToNhomMau!$B:$B,M14),M14,IFERROR(INDEX(DM_YeuToNhomMau!$B:$B,MATCH(M14,DM_YeuToNhomMau!$C:$C,0)),M14))) | AF14: =IF(Q14="","",IF(COUNTIF(DM_TinhThanh!$B:$B,Q14),Q14,IFERROR(INDEX(DM_TinhThanh!$B:$B,MATCH(Q14,DM_TinhThanh!$C:$C,0)),Q14))) | AG14: =IF(R14="","",IF(COUNTIF(DM_XaPhuong!$B:$B,R14),R14,IFERROR(INDEX(DM_XaPhuong!$B:$B,MATCH(R14,DM_XaPhuong!$C:$C,0)),R14))) | AH14: =IF(U14="","",IF(COUNTIF(DM_NoiCongTac!$B:$B,U14),U14,IFERROR(INDEX(DM_NoiCongTac!$B:$B,MATCH(U14,DM_NoiCongTac!$C:$C,0)),U14)))
X15: =IF(B15="","",IF(COUNTIF(DM_DoiTuong!$B:$B,B15),B15,IFERROR(INDEX(DM_DoiTuong!$B:$B,MATCH(B15,DM_DoiTuong!$C:$C,0)),B15))) | Y15: =IF(C15="","",IF(COUNTIF(DM_DiaDiemKham!$B:$B,C15),C15,IFERROR(INDEX(DM_DiaDiemKham!$B:$B,MATCH(C15,DM_DiaDiemKham!$C:$C,0)),C15))) | Z15: =IF(D15="","",IF(COUNTIF(DM_HinhThucChiTra!$B:$B,D15),D15,IFERROR(INDEX(DM_HinhThucChiTra!$B:$B,MATCH(D15,DM_HinhThucChiTra!$C:$C,0)),D15))) | AA15: =IF(E15="","",IF(COUNTIF(DM_HinhThucKham!$B:$B,E15),E15,IFERROR(INDEX(DM_HinhThucKham!$B:$B,MATCH(E15,DM_HinhThucKham!$C:$C,0)),E15))) | AB15: =IF(J15="","",IF(COUNTIF(DM_GioiTinh!$B:$B,J15),J15,IFERROR(INDEX(DM_GioiTinh!$B:$B,MATCH(J15,DM_GioiTinh!$C:$C,0)),J15))) | AC15: =IF(K15="","",IF(COUNTIF(DM_DanToc!$B:$B,K15),K15,IFERROR(INDEX(DM_DanToc!$B:$B,MATCH(K15,DM_DanToc!$C:$C,0)),K15))) | AD15: =IF(L15="","",IF(COUNTIF(DM_NhomMau!$B:$B,L15),L15,IFERROR(INDEX(DM_NhomMau!$B:$B,MATCH(L15,DM_NhomMau!$C:$C,0)),L15))) | AE15: =IF(M15="","",IF(COUNTIF(DM_YeuToNhomMau!$B:$B,M15),M15,IFERROR(INDEX(DM_YeuToNhomMau!$B:$B,MATCH(M15,DM_YeuToNhomMau!$C:$C,0)),M15))) | AF15: =IF(Q15="","",IF(COUNTIF(DM_TinhThanh!$B:$B,Q15),Q15,IFERROR(INDEX(DM_TinhThanh!$B:$B,MATCH(Q15,DM_TinhThanh!$C:$C,0)),Q15))) | AG15: =IF(R15="","",IF(COUNTIF(DM_XaPhuong!$B:$B,R15),R15,IFERROR(INDEX(DM_XaPhuong!$B:$B,MATCH(R15,DM_XaPhuong!$C:$C,0)),R15))) | AH15: =IF(U15="","",IF(COUNTIF(DM_NoiCongTac!$B:$B,U15),U15,IFERROR(INDEX(DM_NoiCongTac!$B:$B,MATCH(U15,DM_NoiCongTac!$C:$C,0)),U15)))
X16: =IF(B16="","",IF(COUNTIF(DM_DoiTuong!$B:$B,B16),B16,IFERROR(INDEX(DM_DoiTuong!$B:$B,MATCH(B16,DM_DoiTuong!$C:$C,0)),B16))) | Y16: =IF(C16="","",IF(COUNTIF(DM_DiaDiemKham!$B:$B,C16),C16,IFERROR(INDEX(DM_DiaDiemKham!$B:$B,MATCH(C16,DM_DiaDiemKham!$C:$C,0)),C16))) | Z16: =IF(D16="","",IF(COUNTIF(DM_HinhThucChiTra!$B:$B,D16),D16,IFERROR(INDEX(DM_HinhThucChiTra!$B:$B,MATCH(D16,DM_HinhThucChiTra!$C:$C,0)),D16))) | AA16: =IF(E16="","",IF(COUNTIF(DM_HinhThucKham!$B:$B,E16),E16,IFERROR(INDEX(DM_HinhThucKham!$B:$B,MATCH(E16,DM_HinhThucKham!$C:$C,0)),E16))) | AB16: =IF(J16="","",IF(COUNTIF(DM_GioiTinh!$B:$B,J16),J16,IFERROR(INDEX(DM_GioiTinh!$B:$B,MATCH(J16,DM_GioiTinh!$C:$C,0)),J16))) | AC16: =IF(K16="","",IF(COUNTIF(DM_DanToc!$B:$B,K16),K16,IFERROR(INDEX(DM_DanToc!$B:$B,MATCH(K16,DM_DanToc!$C:$C,0)),K16))) | AD16: =IF(L16="","",IF(COUNTIF(DM_NhomMau!$B:$B,L16),L16,IFERROR(INDEX(DM_NhomMau!$B:$B,MATCH(L16,DM_NhomMau!$C:$C,0)),L16))) | AE16: =IF(M16="","",IF(COUNTIF(DM_YeuToNhomMau!$B:$B,M16),M16,IFERROR(INDEX(DM_YeuToNhomMau!$B:$B,MATCH(M16,DM_YeuToNhomMau!$C:$C,0)),M16))) | AF16: =IF(Q16="","",IF(COUNTIF(DM_TinhThanh!$B:$B,Q16),Q16,IFERROR(INDEX(DM_TinhThanh!$B:$B,MATCH(Q16,DM_TinhThanh!$C:$C,0)),Q16))) | AG16: =IF(R16="","",IF(COUNTIF(DM_XaPhuong!$B:$B,R16),R16,IFERROR(INDEX(DM_XaPhuong!$B:$B,MATCH(R16,DM_XaPhuong!$C:$C,0)),R16))) | AH16: =IF(U16="","",IF(COUNTIF(DM_NoiCongTac!$B:$B,U16),U16,IFERROR(INDEX(DM_NoiCongTac!$B:$B,MATCH(U16,DM_NoiCongTac!$C:$C,0)),U16)))
... X1000: =IF(B1000="","",IF(COUNTIF(DM_DoiTuong!$B:$B,B1000),B1000,IFERROR(INDEX(DM_DoiTuong!$B:$B,MATCH(B1000,DM_DoiTuong!$C:$C,0)),B1000))) | Y1000: =IF(C1000="","",IF(COUNTIF(DM_DiaDiemKham!$B:$B,C1000),C1000,IFERROR(INDEX(DM_DiaDiemKham!$B:$B,MATCH(C1000,DM_DiaDiemKham!$C:$C,0)),C1000))) | Z1000: =IF(D1000="","",IF(COUNTIF(DM_HinhThucChiTra!$B:$B,D1000),D1000,IFERROR(INDEX(DM_HinhThucChiTra!$B:$B,MATCH(D1000,DM_HinhThucChiTra!$C:$C,0)),D1000))) | AA1000: =IF(E1000="","",IF(COUNTIF(DM_HinhThucKham!$B:$B,E1000),E1000,IFERROR(INDEX(DM_HinhThucKham!$B:$B,MATCH(E1000,DM_HinhThucKham!$C:$C,0)),E1000))) | AB1000: =IF(J1000="","",IF(COUNTIF(DM_GioiTinh!$B:$B,J1000),J1000,IFERROR(INDEX(DM_GioiTinh!$B:$B,MATCH(J1000,DM_GioiTinh!$C:$C,0)),J1000))) | AC1000: =IF(K1000="","",IF(COUNTIF(DM_DanToc!$B:$B,K1000),K1000,IFERROR(INDEX(DM_DanToc!$B:$B,MATCH(K1000,DM_DanToc!$C:$C,0)),K1000))) | AD1000: =IF(L1000="","",IF(COUNTIF(DM_NhomMau!$B:$B,L1000),L1000,IFERROR(INDEX(DM_NhomMau!$B:$B,MATCH(L1000,DM_NhomMau!$C:$C,0)),L1000))) | AE1000: =IF(M1000="","",IF(COUNTIF(DM_YeuToNhomMau!$B:$B,M1000),M1000,IFERROR(INDEX(DM_YeuToNhomMau!$B:$B,MATCH(M1000,DM_YeuToNhomMau!$C:$C,0)),M1000))) | AF1000: =IF(Q1000="","",IF(COUNTIF(DM_TinhThanh!$B:$B,Q1000),Q1000,IFERROR(INDEX(DM_TinhThanh!$B:$B,MATCH(Q1000,DM_TinhThanh!$C:$C,0)),Q1000))) | AG1000: =IF(R1000="","",IF(COUNTIF(DM_XaPhuong!$B:$B,R1000),R1000,IFERROR(INDEX(DM_XaPhuong!$B:$B,MATCH(R1000,DM_XaPhuong!$C:$C,0)),R1000))) | AH1000: =IF(U1000="","",IF(COUNTIF(DM_NoiCongTac!$B:$B,U1000),U1000,IFERROR(INDEX(DM_NoiCongTac!$B:$B,MATCH(U1000,DM_NoiCongTac!$C:$C,0)),U1000)))

Sheet Mapping
A1: CotExcel | B1: FieldAPI | C1: GoiY
A2: NgayKham | B2: NgayKham | C2: dd/MM/yyyy — Ngày khám
A3: DoiTuong | B3: DoiTuong_M13 | C3: Chọn từ sheet DM_DoiTuong (điền Name hoặc Id)
A4: DiaDiemKham | B4: DoiTuongKham | C4: Chọn từ DM_DiaDiemKham
A5: HinhThucChiTra | B5: HinhThucChiTraKhamSK | C5: Chọn từ DM_HinhThucChiTra
A6: HinhThucKham | B6: HinhThucChiTraKhamSK_ChiTiet | C6: Chọn từ DM_HinhThucKham
A7: NguonKhac_GhiRo | B7: NguonKhac_GhiRo | C7: Nếu hình thức chi trả = nguồn khác
A8: CCCD | B8: DinhDanhCaNhan | C8: Số CCCD / định danh / hộ chiếu
A9: HoTen | B9: HoTen | C9: Họ tên IN HOA
A10: NgaySinh | B10: NgaySinh | C10: dd/MM/yyyy
A11: GioiTinh | B11: GioiTinh | C11: Nam hoặc Nữ
A12: DanToc | B12: DanTocId | C12: Chọn từ DM_DanToc (mặc định: Kinh)
... A24: LyDoKham | B24: LyDoKham | C24: Lý do khám sức khỏe

Sheet DM_DoiTuong
A1: Id | B1: Name | C1: TimKiem | D1: GoiY
A2: 1 | B2: Sinh Viên, học viên | D2: Sinh Viên, học viên
A3: 2 | B3: Người lao động (theo pháp luật về an toàn, vệ sinh lao động) | C3: Người lao động | D3: Người lao động (theo pháp luật về an toàn, vệ sinh lao động)
A4: 3 | B4: Người lao động phi chính thức | D4: Người lao động
A5: 4 | B5: Người thuộc nhóm bảo trợ xã hội | D5: Người lao động phi chính thức
A6: 5 | B6: Người cao tuổi | D6: Người thuộc nhóm bảo trợ xã hội
A7: 6 | B7: Người khuyết tật | D7: Người cao tuổi
A8: 7 | B8: Người thuộc hộ nghèo, cận nghèo | D8: Người khuyết tật
A9: 8 | B9: Người có công | D9: Người thuộc hộ nghèo, cận nghèo
A10: 9 | B10: Người mắc bệnh mạn tính | D10: Người có công
A11: 10 | B11: Người sống tại vùng đồng bào dân tộc thiểu số và miền núi | D11: Người mắc bệnh mạn tính
A12: 11 | B12: Người sống tại vùng có điều kiện kinh tế - xã hội khó khăn, đặc biệt khó khăn | D12: Người sống tại vùng đồng bào dân tộc thiểu số và miền núi
A13: 12 | B13: Người sống tại xã đảo | D13: Người sống tại vùng có điều kiện kinh tế - xã hội khó khăn, đặc biệt khó khăn
A14: 13 | B14: Người sống tại đặc khu | D14: Người sống tại xã đảo
A15: 14 | B15: Trẻ dưới 6 tuổi đi học (trẻ đang học mầm non) | C15: Trẻ dưới 6 tuổi đi học | D15: Người sống tại đặc khu
A16: 15 | B16: Trẻ dưới 6 tuổi không đi học | D16: Trẻ dưới 6 tuổi đi học (trẻ đang học mầm non)
A17: 16 | B17: Trẻ từ đủ 6 tuổi đến 18 tuổi đi học (lớp 1 đến lớp 12) | C17: Trẻ từ đủ 6 tuổi đến 18 tuổi đi học | D17: Trẻ dưới 6 tuổi đi học
A18: 17 | B18: Trẻ từ đủ 6 tuổi đến 18 tuổi không đi học | D18: Trẻ dưới 6 tuổi không đi học
A19: 18 | B19: Các đối tượng khác | D19: Trẻ từ đủ 6 tuổi đến 18 tuổi đi học (lớp 1 đến lớp 12)
D20: Trẻ từ đủ 6 tuổi đến 18 tuổi đi học
D21: Trẻ từ đủ 6 tuổi đến 18 tuổi không đi học
D22: Các đối tượng khác

Sheet DM_DiaDiemKham
A1: Id | B1: Name | C1: TimKiem | D1: GoiY
A2: 4052 | B2: Cơ Sở Khám Chữa Bệnh | C2: Khám Chữa Bệnh | D2: Cơ Sở Khám Chữa Bệnh
A3: 4053 | B3: Khám Lưu Động | C3: Lưu Động | D3: Khám Chữa Bệnh
A4: 5057 | B4: Trạm Y Tế | D4: Khám Lưu Động
A5: 5060 | B5: KSK Tại Nhà | D5: Lưu Động
A6: 5131 | B6: Trường Học | D6: Trạm Y Tế
D7: KSK Tại Nhà
D8: Trường Học

Sheet DM_HinhThucChiTra
A1: Id | B1: Name | C1: TimKiem | D1: GoiY
A2: 4039 | B2: Ngân sách thành phố hỗ trợ | C2: thành phố hỗ trợ | D2: Ngân sách thành phố hỗ trợ
A3: 4040 | B3: Người sử dụng lao động chi trả | C3: sử dụng lao động chi trả | D3: thành phố hỗ trợ
A4: 4041 | B4: Người dân tự chi trả | C4: dân tự chi trả | D4: Người sử dụng lao động chi trả
A5: 4042 | B5: Nguồn khác | C5: khác | D5: sử dụng lao động chi trả
D6: Người dân tự chi trả
D7: dân tự chi trả
D8: Nguồn khác
D9: khác

Sheet DM_HinhThucKham
A1: Id | B1: Name | C1: TimKiem | D1: GoiY
A2: 5083 | B2: Khám Theo Hợp Đồng | C2: Theo Hợp Đồng | D2: Khám Theo Hợp Đồng
A3: 5133 | B3: Tự Thực hiện | C3: Thực hiện | D3: Theo Hợp Đồng
D4: Tự Thực hiện
D5: Thực hiện

Sheet DM_GioiTinh
A1: Id | B1: Name | C1: TimKiem | D1: GoiY
A2: 262 | B2: Nữ | D2: Nữ
A3: 263 | B3: Nam | D3: Nam

Sheet DM_DanToc
A1: Id | B1: Name | C1: TimKiem | D1: GoiY
A2: 15 | B2: Kinh | D2: Kinh
A3: 16 | B3: Tày | D3: Tày
A4: 17 | B4: Thái | D4: Thái
A5: 18 | B5: Hoa | D5: Hoa
A6: 19 | B6: Khme | D6: Khme
A7: 20 | B7: Mường | D7: Mường
A8: 21 | B8: Nùng | D8: Nùng
A9: 22 | B9: Hán | D9: Hán
A10: 23 | B10: Dao | D10: Dao
A11: 24 | B11: Gia rai | D11: Gia rai
A12: 25 | B12: Cao lan | D12: Cao lan
A13: 26 | B13: Ê đê | D13: Ê đê
... A77: 1039 | B77: Ve | D77: Khác trong nước
A78: 1040 | B78: Khác trong nước

Sheet DM_NhomMau
A1: Id | B1: Name | C1: TimKiem | D1: GoiY
A2: 1 | B2: A | D2: A
A3: 2 | B3: B | D3: B
A4: 3 | B4: O | D4: O
A5: 4 | B5: AB | D5: AB

Sheet DM_YeuToNhomMau
A1: Id | B1: Name | C1: TimKiem | D1: GoiY
A2: 1 | B2: Rh- | D2: Rh-
A3: 2 | B3: Rh+ | D3: Rh+

Sheet DM_TinhThanh
A1: Id | B1: Name | C1: TimKiem | D1: GoiY
A2: 1 | B2: Thành phố Hà Nội | C2: Hà Nội | D2: Thành phố Hà Nội
A3: 3 | B3: Tỉnh Cao Bằng | C3: Cao Bằng | D3: Hà Nội
A4: 5 | B4: Tỉnh Tuyên Quang | C4: Tuyên Quang | D4: Tỉnh Cao Bằng
A5: 6 | B5: Tỉnh Lào Cai | C5: Lào Cai | D5: Cao Bằng
A6: 7 | B6: Tỉnh Điện Biên | C6: Điện Biên | D6: Tỉnh Tuyên Quang
A7: 8 | B7: Tỉnh Lai Châu | C7: Lai Châu | D7: Tuyên Quang
A8: 9 | B8: Tỉnh Sơn La | C8: Sơn La | D8: Tỉnh Lào Cai
A9: 12 | B9: Tỉnh Thái Nguyên | C9: Thái Nguyên | D9: Lào Cai
A10: 13 | B10: Tỉnh Lạng Sơn | C10: Lạng Sơn | D10: Tỉnh Điện Biên
A11: 14 | B11: Tỉnh Quảng Ninh | C11: Quảng Ninh | D11: Điện Biên
A12: 16 | B12: Tỉnh Phú Thọ | C12: Phú Thọ | D12: Tỉnh Lai Châu
A13: 18 | B13: Tỉnh Bắc Ninh | C13: Bắc Ninh | D13: Lai Châu
... A35: 63 | B35: Tỉnh Cà Mau | C35: Cà Mau | D35: Nghệ An
D36: Tỉnh Hà Tĩnh
D37: Hà Tĩnh
D38: Tỉnh Quảng Trị
D39: Quảng Trị
D40: Thành phố Huế
D41: Huế
D42: Thành phố Đà Nẵng
D43: Đà Nẵng
D44: Tỉnh Quảng Ngãi
D45: Quảng Ngãi
D46: Tỉnh Khánh Hòa
D47: Khánh Hòa
... D69: Cà Mau

Sheet DM_XaPhuong
A1: Id | B1: Name | C1: TimKiem | D1: GoiY
A2: 1 | B2: Phường Hiệp Bình | C2: Hiệp Bình | D2: Phường Hiệp Bình
A3: 2 | B3: Phường Tam Bình | C3: Tam Bình | D3: Hiệp Bình
A4: 3 | B4: Phường Thủ Đức | C4: Thủ Đức | D4: Phường Tam Bình
A5: 4 | B5: Phường Linh Xuân | C5: Linh Xuân | D5: Tam Bình
A6: 5 | B6: Phường Long Bình | C6: Long Bình | D6: Phường Thủ Đức
A7: 6 | B7: Phường Tăng Nhơn Phú | C7: Tăng Nhơn Phú | D7: Thủ Đức
A8: 7 | B8: Phường Phước Long | C8: Phước Long | D8: Phường Linh Xuân
A9: 8 | B9: Phường Long Phước | C9: Long Phước | D9: Linh Xuân
A10: 9 | B10: Phường Long Trường | C10: Long Trường | D10: Phường Long Bình
A11: 10 | B11: Phường An Khánh | C11: An Khánh | D11: Long Bình
A12: 11 | B12: Phường Bình Trưng | C12: Bình Trưng | D12: Phường Tăng Nhơn Phú
A13: 12 | B13: Phường Cát Lái | C13: Cát Lái | D13: Tăng Nhơn Phú
... A132: 131 | B132: Xã Phước Hải | C132: Phước Hải | D132: Phường Cầu Kiệu
A133: 132 | B133: Đặc khu Côn Đảo | D133: Cầu Kiệu
A134: 133 | B134: Phường Thới Hòa | C134: Thới Hòa | D134: Phường Phú Nhuận
A135: 134 | B135: Phường Đông Hòa | C135: Đông Hòa | D135: Phú Nhuận
A136: 135 | B136: Phường Dĩ An | C136: Dĩ An | D136: Phường Tân Sơn Hòa
A137: 136 | B137: Phường Tân Đông Hiệp | C137: Tân Đông Hiệp | D137: Tân Sơn Hòa
A138: 137 | B138: Phường Thuận An | C138: Thuận An | D138: Phường Tân Sơn Nhất
A139: 138 | B139: Phường Thuận Giao | C139: Thuận Giao | D139: Tân Sơn Nhất
A140: 139 | B140: Phường Bình Hòa | C140: Bình Hòa | D140: Phường Tân Hòa
A141: 140 | B141: Phường Lái Thiêu | C141: Lái Thiêu | D141: Tân Hòa
A142: 141 | B142: Phường An Phú | C142: An Phú | D142: Phường Bảy Hiền
A143: 142 | B143: Phường Bình Dương | C143: Bình Dương | D143: Bảy Hiền
A144: 143 | B144: Phường Chánh Hiệp | C144: Chánh Hiệp | D144: Phường Tân Bình
A145: 144 | B145: Phường Thủ Dầu Một | C145: Thủ Dầu Một | D145: Tân Bình
... A169: 168 | B169: Xã Thanh An | C169: Thanh An | D169: Hưng Long
D170: Xã Bình Hưng
D171: Bình Hưng
D172: Xã Cần Giờ
D173: Cần Giờ
D174: Xã An Thới Đông
D175: An Thới Đông
D176: Xã Bình Khánh
D177: Bình Khánh
D178: Xã Thạnh An
D179: Thạnh An
D180: Xã An Nhơn Tây
D181: An Nhơn Tây
...

Sheet DM_NgheNghiep
A1: Id | B1: Name
A2: 227 | B2: Tổng Bí thư, Thường trực Ban Bí thư, Ban Bí thư, Ủy viên Bộ Chính trị, Ủy viên Ban Chấp hành Trung ương Đảng
A3: 228 | B3: Bí thư, Phó Bí thư Đảng ủy cơ quan trung ương
A4: 229 | B4: Bí thư, Phó Bí thư Đảng ủy khối trực thuộc trung ương
A5: 230 | B5: Trưởng ban, Phó Trưởng ban Đảng và tương đương thuộc cấp trung ương
A6: 231 | B6: Trợ lý Ủy viên Bộ Chính trị
A7: 232 | B7: Vụ trưởng, Phó Vụ trưởng và tương đương
A8: 233 | B8: Bí thư Tỉnh ủy, Phó Bí thư Tỉnh ủy, Ủy viên Ban Chấp hành Đảng bộ cấp tỉnh
A9: 234 | B9: Bí thư, Phó Bí thư Đảng ủy sở, ban, ngành cấp tỉnh
A10: 235 | B10: Bí thư, Phó Bí thư Đảng ủy khối cơ quan cấp tỉnh
A11: 236 | B11: Trưởng ban, Phó Trưởng ban Đảng và tương đương thuộc cấp tỉnh

Sheet DM_NoiCongTac
A1: Id | B1: Name | C1: TimKiem | D1: GoiY
A2: 1 | B2: Phòng khám đa khoa thuộc Công ty Cổ phần Bệnh viện Quốc tế European Wellness | C2: Công ty Cổ phần Bệnh viện Quốc tế European Wellness | D2: Phòng khám đa khoa thuộc Công ty Cổ phần Bệnh viện Quốc tế European Wellness
A3: 2 | B3: Phòng khám đa khoa thuộc Công ty TNHH Phòng khám đa khoa Đi Cờ Li Nít | C3: Công ty TNHH Phòng khám đa khoa Đi Cờ Li Nít | D3: Công ty Cổ phần Bệnh viện Quốc tế European Wellness
A4: 3 | B4: Phòng khám đa khoa thuộc Công ty Cổ phần Vigor Anbis Japan | C4: Công ty Cổ phần Vigor Anbis Japan | D4: Phòng khám đa khoa thuộc Công ty TNHH Phòng khám đa khoa Đi Cờ Li Nít
A5: 4 | B5: Phòng khám đa khoa thuộc Công ty Cổ phần Y tế Tao Đàn | C5: Công ty Cổ phần Y tế Tao Đàn | D5: Công ty TNHH Phòng khám đa khoa Đi Cờ Li Nít
A6: 5 | B6: Phòng khám đa khoa thuộc Chi nhánh Công ty Cổ phần Phát triển Y tế Victoria Healthcare - Phòng khám đa khoa ĐTH | C6: Công ty Cổ phần Phát triển Y tế Victoria Healthcare - Phòng khám đa khoa ĐTH | D6: Phòng khám đa khoa thuộc Công ty Cổ phần Vigor Anbis Japan
A7: 6 | B7: Phòng khám đa khoa thuộc Công ty Cổ phần Phòng khám Gia đình Thành phố Hồ Chí Minh (Phòng khám số 1) | C7: Công ty Cổ phần Phòng khám Gia đình Thành phố Hồ Chí Minh (Phòng khám số 1) | D7: Công ty Cổ phần Vigor Anbis Japan
A8: 7 | B8: Phòng khám đa khoa thuộc Phòng khám đa khoa DHA Healthcare (thuộc Công ty Cổ phần Thương mại Dịch vụ Y tế DHA) | C8: Phòng khám đa khoa DHA Healthcare (thuộc Công ty Cổ phần Thương mại Dịch vụ Y tế DHA) | D8: Phòng khám đa khoa thuộc Công ty Cổ phần Y tế Tao Đàn
A9: 8 | B9: Phòng khám đa khoa thuộc Công ty TNHH Dym Medical Center Việt Nam | C9: Công ty TNHH Dym Medical Center Việt Nam | D9: Công ty Cổ phần Y tế Tao Đàn
A10: 9 | B10: Phòng khám đa khoa thuộc Phòng khám đa khoa Hoa Sen | C10: Phòng khám đa khoa Hoa Sen | D10: Phòng khám đa khoa thuộc Chi nhánh Công ty Cổ phần Phát triển Y tế Victoria Healthcare - Phòng khám đa khoa ĐTH
A11: 10 | B11: Phòng khám đa khoa Intermec - Chi nhánh Công ty TNHH Phòng khám đa khoa Intermec | D11: Công ty Cổ phần Phát triển Y tế Victoria Healthcare - Phòng khám đa khoa ĐTH
D12: Phòng khám đa khoa thuộc Công ty Cổ phần Phòng khám Gia đình Thành phố Hồ Chí Minh (Phòng khám số 1)
D13: Công ty Cổ phần Phòng khám Gia đình Thành phố Hồ Chí Minh (Phòng khám số 1)
D14: Phòng khám đa khoa thuộc Phòng khám đa khoa DHA Healthcare (thuộc Công ty Cổ phần Thương mại Dịch vụ Y tế DHA)
D15: Phòng khám đa khoa DHA Healthcare (thuộc Công ty Cổ phần Thương mại Dịch vụ Y tế DHA)
D16: Phòng khám đa khoa thuộc Công ty TNHH Dym Medical Center Việt Nam
D17: Công ty TNHH Dym Medical Center Việt Nam
D18: Phòng khám đa khoa thuộc Phòng khám đa khoa Hoa Sen
D19: Phòng khám đa khoa Hoa Sen
D20: Phòng khám đa khoa Intermec - Chi nhánh Công ty TNHH Phòng khám đa khoa Intermec

Sheet _Lookup
A1: Sheet | B1: Official | C1: TimKiem
A2: DM_DanToc | B2: Kinh
A3: DM_DanToc | B3: Tày
A4: DM_DanToc | B4: Thái
A5: DM_DanToc | B5: Hoa
A6: DM_DanToc | B6: Khme
A7: DM_DanToc | B7: Mường
A8: DM_DanToc | B8: Nùng
A9: DM_DanToc | B9: Hán
A10: DM_DanToc | B10: Dao
A11: DM_DanToc | B11: Gia rai
A12: DM_DanToc | B12: Cao lan
A13: DM_DanToc | B13: Ê đê
... A78: DM_DanToc | B78: Khác trong nước
A79: DM_DiaDiemKham | B79: Cơ Sở Khám Chữa Bệnh | C79: Khám Chữa Bệnh
A80: DM_DiaDiemKham | B80: Khám Lưu Động | C80: Lưu Động
A81: DM_DiaDiemKham | B81: Trạm Y Tế
A82: DM_DiaDiemKham | B82: KSK Tại Nhà
A83: DM_DiaDiemKham | B83: Trường Học
A84: DM_DoiTuong | B84: Sinh Viên, học viên
A85: DM_DoiTuong | B85: Người lao động (theo pháp luật về an toàn, vệ sinh lao động) | C85: Người lao động
A86: DM_DoiTuong | B86: Người lao động phi chính thức
A87: DM_DoiTuong | B87: Người thuộc nhóm bảo trợ xã hội
A88: DM_DoiTuong | B88: Người cao tuổi
A89: DM_DoiTuong | B89: Người khuyết tật
A90: DM_DoiTuong | B90: Người thuộc hộ nghèo, cận nghèo
A91: DM_DoiTuong | B91: Người có công
A92: DM_DoiTuong | B92: Người mắc bệnh mạn tính
A93: DM_DoiTuong | B93: Người sống tại vùng đồng bào dân tộc thiểu số và miền núi
A94: DM_DoiTuong | B94: Người sống tại vùng có điều kiện kinh tế - xã hội khó khăn, đặc biệt khó khăn
A95: DM_DoiTuong | B95: Người sống tại xã đảo
A96: DM_DoiTuong | B96: Người sống tại đặc khu
A97: DM_DoiTuong | B97: Trẻ dưới 6 tuổi đi học (trẻ đang học mầm non) | C97: Trẻ dưới 6 tuổi đi học
A98: DM_DoiTuong | B98: Trẻ dưới 6 tuổi không đi học
A99: DM_DoiTuong | B99: Trẻ từ đủ 6 tuổi đến 18 tuổi đi học (lớp 1 đến lớp 12) | C99: Trẻ từ đủ 6 tuổi đến 18 tuổi đi học
A100: DM_DoiTuong | B100: Trẻ từ đủ 6 tuổi đến 18 tuổi không đi học
A101: DM_DoiTuong | B101: Các đối tượng khác
A102: DM_GioiTinh | B102: Nữ
A103: DM_GioiTinh | B103: Nam
A104: DM_HinhThucChiTra | B104: Ngân sách thành phố hỗ trợ | C104: thành phố hỗ trợ
...
